Traceback (most recent call last):
  File "/opt/hostedtoolcache/Python/3.9.7/x64/lib/python3.9/site-packages/jupyter_cache/executors/utils.py", line 51, in single_nb_execution
    executenb(
  File "/opt/hostedtoolcache/Python/3.9.7/x64/lib/python3.9/site-packages/nbclient/client.py", line 1117, in execute
    return NotebookClient(nb=nb, resources=resources, km=km, **kwargs).execute()
  File "/opt/hostedtoolcache/Python/3.9.7/x64/lib/python3.9/site-packages/nbclient/util.py", line 78, in wrapped
    return just_run(coro(*args, **kwargs))
  File "/opt/hostedtoolcache/Python/3.9.7/x64/lib/python3.9/site-packages/nbclient/util.py", line 57, in just_run
    return loop.run_until_complete(coro)
  File "/opt/hostedtoolcache/Python/3.9.7/x64/lib/python3.9/asyncio/base_events.py", line 642, in run_until_complete
    return future.result()
  File "/opt/hostedtoolcache/Python/3.9.7/x64/lib/python3.9/site-packages/nbclient/client.py", line 558, in async_execute
    await self.async_execute_cell(
  File "/opt/hostedtoolcache/Python/3.9.7/x64/lib/python3.9/site-packages/nbclient/client.py", line 862, in async_execute_cell
    self._check_raise_for_error(cell, exec_reply)
  File "/opt/hostedtoolcache/Python/3.9.7/x64/lib/python3.9/site-packages/nbclient/client.py", line 765, in _check_raise_for_error
    raise CellExecutionError.from_cell_and_msg(cell, exec_reply_content)
nbclient.exceptions.CellExecutionError: An error occurred while executing the following cell:
------------------
from scipy.stats import norm
for i in range(5):
mean_buckle_load, std_buckle_load, p_dist = montecarlo_buckle(200e9,0.01,0.001,5)
print(norm.ppf(0.975, mean_buckle_load, std_buckle_load))
------------------

[0;36m  File [0;32m"/tmp/ipykernel_1796/3510244900.py"[0;36m, line [0;32m3[0m
[0;31m    mean_buckle_load, std_buckle_load, p_dist = montecarlo_buckle(200e9,0.01,0.001,5)[0m
[0m    ^[0m
[0;31mIndentationError[0m[0;31m:[0m expected an indented block

IndentationError: expected an indented block (3510244900.py, line 3)

